Workbook

Sheet Sheet1
E1: Next Steps
B2: Email Type | C2: When (Broad Stage) ? | D2: Intent | E2: Step 1 | F2: Step 2 | G2: Step 3 | H2: Step 4 | I2: Step 5 | J2: Step 6 | K2: Step 7 | L2: Step 8 | M2: Step 9 | N2: Step 10 | O2: Step 11 | P2: Step 12 | Q2: Step 13 | R2: Step 14
B3: Branch Email | C3: Before LS Creation | D3: New SO | I3: ZSO_Visibility + Zmatana | J3: Email to Branch to confirm product details | K3: Email to Branch to confirm bundle details | L3: ZLOAD1 | O3: Email to Branch for Vehicle | P3: Email to Plant | Q3: Zload3 + ZSO_Auto | R3: VT01N
B4: Branch Email | C4: Before LS Creation | D4: Second Release confirmation
B5: Branch Email | C5: Before LS Creation | D5: Vehicle Weight Clarification | L5: ZLOAD1 | O5: Email to Branch for Vehicle | P5: Email to Plant | Q5: Zload3 + ZSO_Auto | R5: VT01N
B6: Branch Email | C6: Anytime | D6: Seeking Order Update
B7: Branch Email | C7: After LS Creation | D7: Sharing Vehicle Details | O7: Email to Branch for Vehicle | P7: Email to Plant | Q7: Zload3 + ZSO_Auto | R7: VT01N
B8: Branch Email | C8: Anytime | D8: Others
A9: 1 | B9: Branch Email | C9: Before LS Creation | D9: Product Clarification - Release All - No Change in SO quantity | I9: ZSO_Visibility + Zmatana | J9: Email to Branch to confirm product details | K9: Email to Branch to confirm bundle details | L9: ZLOAD1 | O9: Email to Branch for Vehicle | P9: Email to Plant | Q9: Zload3 + ZSO_Auto | R9: VT01N
A10: 2 | B10: Branch Email | C10: Before LS Creation | D10: Product Clarification - Release as available/part - Decrease in SO quantity | I10: ZSO_Visibility + Zmatana | J10: Email to Branch to confirm product details | K10: Email to Branch to confirm bundle details | L10: ZLOAD1 | O10: Email to Branch for Vehicle | P10: Email to Plant | Q10: Zload3 + ZSO_Auto | R10: VT01N
A11: 4 | B11: Branch Email | C11: Before LS Creation | D11: Product Clarification - Release with adjustment - Increase | F11: Zmatana | G11: VA02 | H11: Email for 2nd Release | I11: ZSO_Visibility + Zmatana | J11: Email to Branch to confirm product details | K11: Email to Branch to confirm bundle details | L11: ZLOAD1 | O11: Email to Branch for Vehicle | P11: Email to Plant | Q11: Zload3 + ZSO_Auto | R11: VT01N
A12: 7 | B12: Branch Email | C12: Before LS Creation | D12: Product Clarification - Release with adjustment - Increase + Decrease | F12: Zmatana | G12: VA02 | H12: Email for 2nd Release | I12: ZSO_Visibility + Zmatana | J12: Email to Branch to confirm product details | K12: Email to Branch to confirm bundle details | L12: ZLOAD1 | O12: Email to Branch for Vehicle | P12: Email to Plant | Q12: Zload3 + ZSO_Auto | R12: VT01N
A13: 8 | B13: Branch Email | C13: Before LS Creation | D13: Product Clarification - Release with adjustment - Increase + Delete | F13: Zmatana | G13: VA02 | H13: Email for 2nd Release | I13: ZSO_Visibility + Zmatana | J13: Email to Branch to confirm product details | K13: Email to Branch to confirm bundle details | L13: ZLOAD1 | O13: Email to Branch for Vehicle | P13: Email to Plant | Q13: Zload3 + ZSO_Auto | R13: VT01N
A14: 6 | B14: Branch Email | C14: Before LS Creation | D14: Product Clarification - Release with adjustment - Delete | L14: ZLOAD1 | O14: Email to Branch for Vehicle | P14: Email to Plant | Q14: Zload3 + ZSO_Auto | R14: VT01N
A15: 3 | B15: Branch Email | C15: Before LS Creation | D15: Product Clarification - Hold/Wait till all material available | E15: MB51
A16: 10 | B16: Branch Email | C16: After LS Creation | D16: SO Modification - Increase | F16: Zmatana | G16: VA02 | H16: Email for 2nd Release | I16: ZSO_Visibility + Zmatana | J16: Email to Branch to confirm product details | K16: Email to Branch to confirm bundle details | M16: ZLOAD2 | P16: Email to Plant | Q16: Zload3 + ZSO_Auto | R16: VT01N
A17: 13 | B17: Branch Email | C17: After LS Creation | D17: SO Modification - Increase + Decrease | F17: Zmatana | G17: VA02 | H17: Email for 2nd Release | I17: ZSO_Visibility + Zmatana | J17: Email to Branch to confirm product details | K17: Email to Branch to confirm bundle details | M17: ZLOAD2 | P17: Email to Plant | Q17: Zload3 + ZSO_Auto | R17: VT01N
A18: 14 | B18: Branch Email | C18: After LS Creation | D18: SO Modification - Increase + Delete | F18: Zmatana | G18: VA02 | H18: Email for 2nd Release | I18: ZSO_Visibility + Zmatana | J18: Email to Branch to confirm product details | K18: Email to Branch to confirm bundle details | M18: ZLOAD2 | N18: ZLOAD_Delete | P18: Email to Plant | Q18: Zload3 + ZSO_Auto | R18: VT01N
A19: 11 | B19: Branch Email | C19: After LS Creation | D19: SO Modification - Decrease | M19: ZLOAD2 | P19: Email to Plant | Q19: Zload3 + ZSO_Auto | R19: VT01N
A20: 12 | B20: Branch Email | C20: After LS Creation | D20: SO Modification - Delete | N20: ZLOAD_Delete | P20: Email to Plant | Q20: Zload3 + ZSO_Auto | R20: VT01N
A21: 15 | B21: Branch Email | C21: AFter LS Creation | D21: SO Modification - Decrease + Delete | M21: ZLOAD2 | N21: ZLOAD_Delete | P21: Email to Plant | Q21: Zload3 + ZSO_Auto | R21: VT01N
B23: Plant Email | C23: After Plant Invoice | D23: Invoice Sent | Q23: Zload3 + ZSO_Auto | R23: VT01N
B24: Plant Email | C24: Anytime | D24: Other
A25: 16 | B25: Plant Email | C25: Before Plant Invoice | D25: LS Modification - Increase | F25: Zmatana | G25: VA02 | H25: Email for 2nd Release | I25: ZSO_Visibility + Zmatana | J25: Email to Branch to confirm product details | K25: Email to Branch to confirm bundle details | M25: ZLOAD2 | P25: Email to Plant | Q25: Zload3 + ZSO_Auto | R25: VT01N
A26: 19 | B26: Plant Email | C26: Before Plant Invoice | D26: LS Modification - Increase + Decrease | F26: Zmatana | G26: VA02 | H26: Email for 2nd Release | I26: ZSO_Visibility + Zmatana | J26: Email to Branch to confirm product details | K26: Email to Branch to confirm bundle details | M26: ZLOAD2 | P26: Email to Plant | Q26: Zload3 + ZSO_Auto | R26: VT01N
A27: 20 | B27: Plant Email | C27: Before Plant Invoice | D27: LS Modification - Increase + Delete | F27: Zmatana | G27: VA02 | H27: Email for 2nd Release | I27: ZSO_Visibility + Zmatana | J27: Email to Branch to confirm product details | K27: Email to Branch to confirm bundle details | M27: ZLOAD2 | N27: ZLOAD_Delete | P27: Email to Plant | Q27: Zload3 + ZSO_Auto | R27: VT01N
A28: 17 | B28: Plant Email | C28: Before Plant Invoice | D28: LS Modification - Decrease | M28: ZLOAD2 | P28: Email to Plant | Q28: Zload3 + ZSO_Auto | R28: VT01N
A29: 18 | B29: Plant Email | C29: Before Plant Invoice | D29: LS Modification - Delete | N29: ZLOAD_Delete | P29: Email to Plant | Q29: Zload3 + ZSO_Auto | R29: VT01N
A30: 21 | B30: Plant Email | C30: Before Plant Invoice | D30: LS Modification - Decrease + Delete | M30: ZLOAD2 | N30: ZLOAD_Delete | P30: Email to Plant | Q30: Zload3 + ZSO_Auto | R30: VT01N
A32: 26 | B32: Branch Email | C32: Before LS Creation | D32: SO Modification - Increase | F32: Zmatana | G32: VA02 | H32: Email for 2nd Release | I32: ZSO_Visibility + Zmatana | J32: Email to Branch to confirm product details | K32: Email to Branch to confirm bundle details | L32: ZLOAD1 | P32: Email to Plant | Q32: Zload3 + ZSO_Auto | R32: VT01N
A33: 27 | B33: Branch Email | C33: Before LS Creation | D33: SO Modification - Increase + Decrease | F33: Zmatana | G33: VA02 | H33: Email for 2nd Release | I33: ZSO_Visibility + Zmatana | J33: Email to Branch to confirm product details | K33: Email to Branch to confirm bundle details | L33: ZLOAD1 | P33: Email to Plant | Q33: Zload3 + ZSO_Auto | R33: VT01N
A34: 28 | B34: Branch Email | C34: Before LS Creation | D34: SO Modification - Increase + Delete | F34: Zmatana | G34: VA02 | H34: Email for 2nd Release | I34: ZSO_Visibility + Zmatana | J34: Email to Branch to confirm product details | K34: Email to Branch to confirm bundle details | L34: ZLOAD1 | P34: Email to Plant | Q34: Zload3 + ZSO_Auto | R34: VT01N
A35: 30 | B35: Branch Email | C35: Before LS Creation | D35: SO Modification - Decrease | L35: ZLOAD1 | P35: Email to Plant | Q35: Zload3 + ZSO_Auto | R35: VT01N
A36: 29 | B36: Branch Email | C36: Before LS Creation | D36: SO Modification - Delete | L36: ZLOAD1 | P36: Email to Plant | Q36: Zload3 + ZSO_Auto | R36: VT01N
A37: 31 | B37: Branch Email | C37: Before LS Creation | D37: SO Modification - Decrease + Delete | L37: ZLOAD1 | P37: Email to Plant | Q37: Zload3 + ZSO_Auto | R37: VT01N

Sheet Copy of Sheet1
E1: Next Steps
A2: Email Type | B2: When (Broad Stage) ? | C2: Intent | E2: Step 1 | F2: Step 2 | G2: Step 3 | H2: Step 4 | I2: Step 5 | J2: Step 6 | K2: Step 7 | L2: Step 8 | M2: Step 9 | N2: Step 10 | O2: Step 11 | P2: Step 12 | Q2: Step 13 | R2: Step 14
A3: Branch Email | B3: Before LS Creation | C3: New SO | D3: =A3&" - "&B3&" - "&C3 -> Branch Email - Before LS Creation - New SO | I3: ZSO_Visibility + Zmatana | J3: Email to Branch to confirm product details | K3: Email to Branch to confirm bundle details | L3: ZLOAD1 | O3: Email to Branch for Vehicle | P3: Email to Plant | Q3: Zload3 + ZSO_Auto | R3: VT01N
A4: Branch Email | B4: Before LS Creation | C4: Second Release confirmation | D4: =A4&" - "&B4&" - "&C4 -> Branch Email - Before LS Creation - Second Release confirmation
A5: Branch Email | B5: Before LS Creation | C5: Discount Code Confirmation | D5: =A5&" - "&B5&" - "&C5 -> Branch Email - Before LS Creation - Discount Code Confirmation
A6: Branch Email | B6: Before LS Creation | C6: Vehicle Weight Clarification | D6: =A6&" - "&B6&" - "&C6 -> Branch Email - Before LS Creation - Vehicle Weight Clarification | L6: ZLOAD1 | O6: Email to Branch for Vehicle | P6: Email to Plant | Q6: Zload3 + ZSO_Auto | R6: VT01N
A7: Branch Email | B7: Anytime | C7: Seeking Order Update | D7: =A7&" - "&B7&" - "&C7 -> Branch Email - Anytime - Seeking Order Update
A8: Branch Email | B8: After LS Creation | C8: Sharing Vehicle Details | D8: =A8&" - "&B8&" - "&C8 -> Branch Email - After LS Creation - Sharing Vehicle Details | O8: Email to Branch for Vehicle | P8: Email to Plant | Q8: Zload3 + ZSO_Auto | R8: VT01N
A9: Branch Email | B9: Anytime | C9: Others | D9: =A9&" - "&B9&" - "&C9 -> Branch Email - Anytime - Others
A10: Branch Email | B10: Before LS Creation | C10: Product Clarification - Release All - No Change in SO quantity | D10: =A10&" - "&B10&" - "&C10 -> Branch Email - Before LS Creation - Product Clarification - Release All - No Change in SO quantity | I10: ZSO_Visibility + Zmatana | J10: Email to Branch to confirm product details | K10: Email to Branch to confirm bundle details | L10: ZLOAD1 | O10: Email to Branch for Vehicle | P10: Email to Plant | Q10: Zload3 + ZSO_Auto | R10: VT01N
A11: Branch Email | B11: Before LS Creation | C11: Product Clarification - Release as available/part - Decrease in SO quantity | D11: =A11&" - "&B11&" - "&C11 -> Branch Email - Before LS Creation - Product Clarification - Release as available/part - Decrease in SO quantity | I11: ZSO_Visibility + Zmatana | J11: Email to Branch to confirm product details | K11: Email to Branch to confirm bundle details | L11: ZLOAD1 | O11: Email to Branch for Vehicle | P11: Email to Plant | Q11: Zload3 + ZSO_Auto | R11: VT01N
A12: Branch Email | B12: Before LS Creation | C12: Product Clarification - Release with adjustment - Increase | D12: =A12&" - "&B12&" - "&C12 -> Branch Email - Before LS Creation - Product Clarification - Release with adjustment - Increase | F12: Zmatana | G12: VA02 | H12: Email for 2nd Release | I12: ZSO_Visibility + Zmatana | J12: Email to Branch to confirm product details | K12: Email to Branch to confirm bundle details | L12: ZLOAD1 | O12: Email to Branch for Vehicle | P12: Email to Plant | Q12: Zload3 + ZSO_Auto | R12: VT01N
A13: Branch Email | B13: Before LS Creation | C13: Product Clarification - Release with adjustment - Increase + Decrease | D13: =A13&" - "&B13&" - "&C13 -> Branch Email - Before LS Creation - Product Clarification - Release with adjustment - Increase + Decrease | F13: Zmatana | G13: VA02 | H13: Email for 2nd Release | I13: ZSO_Visibility + Zmatana | J13: Email to Branch to confirm product details | K13: Email to Branch to confirm bundle details | L13: ZLOAD1 | O13: Email to Branch for Vehicle | P13: Email to Plant | Q13: Zload3 + ZSO_Auto | R13: VT01N
A14: Branch Email | B14: Before LS Creation | C14: Product Clarification - Release with adjustment - Increase + Delete | D14: =A14&" - "&B14&" - "&C14 -> Branch Email - Before LS Creation - Product Clarification - Release with adjustment - Increase + Delete | F14: Zmatana | G14: VA02 | H14: Email for 2nd Release | I14: ZSO_Visibility + Zmatana | J14: Email to Branch to confirm product details | K14: Email to Branch to confirm bundle details | L14: ZLOAD1 | O14: Email to Branch for Vehicle | P14: Email to Plant | Q14: Zload3 + ZSO_Auto | R14: VT01N
A15: Branch Email | B15: Before LS Creation | C15: Product Clarification - Release with adjustment - Delete | D15: =A15&" - "&B15&" - "&C15 -> Branch Email - Before LS Creation - Product Clarification - Release with adjustment - Delete | L15: ZLOAD1 | O15: Email to Branch for Vehicle | P15: Email to Plant | Q15: Zload3 + ZSO_Auto | R15: VT01N
A16: Branch Email | B16: Before LS Creation | C16: Product Clarification - Hold/Wait till all material available | D16: =A16&" - "&B16&" - "&C16 -> Branch Email - Before LS Creation - Product Clarification - Hold/Wait till all material available | E16: MB51
A17: Branch Email | B17: After LS Creation | C17: SO Modification - Increase | D17: =A17&" - "&B17&" - "&C17 -> Branch Email - After LS Creation - SO Modification - Increase | F17: Zmatana | G17: VA02 | H17: Email for 2nd Release | I17: ZSO_Visibility + Zmatana | J17: Email to Branch to confirm product details | K17: Email to Branch to confirm bundle details | M17: ZLOAD2 | P17: Email to Plant | Q17: Zload3 + ZSO_Auto | R17: VT01N
A18: Branch Email | B18: After LS Creation | C18: SO Modification - Increase + Decrease | D18: =A18&" - "&B18&" - "&C18 -> Branch Email - After LS Creation - SO Modification - Increase + Decrease | F18: Zmatana | G18: VA02 | H18: Email for 2nd Release | I18: ZSO_Visibility + Zmatana | J18: Email to Branch to confirm product details | K18: Email to Branch to confirm bundle details | M18: ZLOAD2 | P18: Email to Plant | Q18: Zload3 + ZSO_Auto | R18: VT01N
A19: Branch Email | B19: After LS Creation | C19: SO Modification - Increase + Delete | D19: =A19&" - "&B19&" - "&C19 -> Branch Email - After LS Creation - SO Modification - Increase + Delete | F19: Zmatana | G19: VA02 | H19: Email for 2nd Release | I19: ZSO_Visibility + Zmatana | J19: Email to Branch to confirm product details | K19: Email to Branch to confirm bundle details | M19: ZLOAD2 | N19: ZLOAD_Delete | P19: Email to Plant | Q19: Zload3 + ZSO_Auto | R19: VT01N
A20: Branch Email | B20: After LS Creation | C20: SO Modification - Decrease | D20: =A20&" - "&B20&" - "&C20 -> Branch Email - After LS Creation - SO Modification - Decrease | M20: ZLOAD2 | P20: Email to Plant | Q20: Zload3 + ZSO_Auto | R20: VT01N
A21: Branch Email | B21: After LS Creation | C21: SO Modification - Delete | D21: =A21&" - "&B21&" - "&C21 -> Branch Email - After LS Creation - SO Modification - Delete | N21: ZLOAD_Delete | P21: Email to Plant | Q21: Zload3 + ZSO_Auto | R21: VT01N
A22: Branch Email | B22: AFter LS Creation | C22: SO Modification - Decrease + Delete | D22: =A22&" - "&B22&" - "&C22 -> Branch Email - AFter LS Creation - SO Modification - Decrease + Delete | M22: ZLOAD2 | N22: ZLOAD_Delete | P22: Email to Plant | Q22: Zload3 + ZSO_Auto | R22: VT01N
D23: =A23&" - "&B23&" - "&C23 -> - -
A24: Plant Email | B24: After Plant Invoice | C24: Invoice Sent | D24: =A24&" - "&B24&" - "&C24 -> Plant Email - After Plant Invoice - Invoice Sent | Q24: Zload3 + ZSO_Auto | R24: VT01N
A25: Plant Email | B25: Anytime | C25: Other | D25: =A25&" - "&B25&" - "&C25 -> Plant Email - Anytime - Other
A26: Plant Email | B26: Before Plant Invoice | C26: LS Modification - Increase | D26: =A26&" - "&B26&" - "&C26 -> Plant Email - Before Plant Invoice - LS Modification - Increase | F26: Zmatana | G26: VA02 | H26: Email for 2nd Release | I26: ZSO_Visibility + Zmatana | J26: Email to Branch to confirm product details | K26: Email to Branch to confirm bundle details | M26: ZLOAD2 | P26: Email to Plant | Q26: Zload3 + ZSO_Auto | R26: VT01N
A27: Plant Email | B27: Before Plant Invoice | C27: LS Modification - Increase + Decrease | D27: =A27&" - "&B27&" - "&C27 -> Plant Email - Before Plant Invoice - LS Modification - Increase + Decrease | F27: Zmatana | G27: VA02 | H27: Email for 2nd Release | I27: ZSO_Visibility + Zmatana | J27: Email to Branch to confirm product details | K27: Email to Branch to confirm bundle details | M27: ZLOAD2 | P27: Email to Plant | Q27: Zload3 + ZSO_Auto | R27: VT01N
A28: Plant Email | B28: Before Plant Invoice | C28: LS Modification - Increase + Delete | D28: =A28&" - "&B28&" - "&C28 -> Plant Email - Before Plant Invoice - LS Modification - Increase + Delete | F28: Zmatana | G28: VA02 | H28: Email for 2nd Release | I28: ZSO_Visibility + Zmatana | J28: Email to Branch to confirm product details | K28: Email to Branch to confirm bundle details | M28: ZLOAD2 | N28: ZLOAD_Delete | P28: Email to Plant | Q28: Zload3 + ZSO_Auto | R28: VT01N
A29: Plant Email | B29: Before Plant Invoice | C29: LS Modification - Decrease | D29: =A29&" - "&B29&" - "&C29 -> Plant Email - Before Plant Invoice - LS Modification - Decrease | M29: ZLOAD2 | P29: Email to Plant | Q29: Zload3 + ZSO_Auto | R29: VT01N
A30: Plant Email | B30: Before Plant Invoice | C30: LS Modification - Delete | D30: =A30&" - "&B30&" - "&C30 -> Plant Email - Before Plant Invoice - LS Modification - Delete | N30: ZLOAD_Delete | P30: Email to Plant | Q30: Zload3 + ZSO_Auto | R30: VT01N
A31: Plant Email | B31: Before Plant Invoice | C31: LS Modification - Decrease + Delete | D31: =A31&" - "&B31&" - "&C31 -> Plant Email - Before Plant Invoice - LS Modification - Decrease + Delete | M31: ZLOAD2 | N31: ZLOAD_Delete | P31: Email to Plant | Q31: Zload3 + ZSO_Auto | R31: VT01N
D32: =A32&" - "&B32&" - "&C32 -> - -
A33: Branch Email | B33: Before LS Creation | C33: SO Modification - Increase | D33: =A33&" - "&B33&" - "&C33 -> Branch Email - Before LS Creation - SO Modification - Increase | F33: Zmatana | G33: VA02 | H33: Email for 2nd Release | I33: ZSO_Visibility + Zmatana | J33: Email to Branch to confirm product details | K33: Email to Branch to confirm bundle details | L33: ZLOAD1 | P33: Email to Plant | Q33: Zload3 + ZSO_Auto | R33: VT01N
A34: Branch Email | B34: Before LS Creation | C34: SO Modification - Increase + Decrease | D34: =A34&" - "&B34&" - "&C34 -> Branch Email - Before LS Creation - SO Modification - Increase + Decrease | F34: Zmatana | G34: VA02 | H34: Email for 2nd Release | I34: ZSO_Visibility + Zmatana | J34: Email to Branch to confirm product details | K34: Email to Branch to confirm bundle details | L34: ZLOAD1 | P34: Email to Plant | Q34: Zload3 + ZSO_Auto | R34: VT01N
A35: Branch Email | B35: Before LS Creation | C35: SO Modification - Increase + Delete | D35: =A35&" - "&B35&" - "&C35 -> Branch Email - Before LS Creation - SO Modification - Increase + Delete | F35: Zmatana | G35: VA02 | H35: Email for 2nd Release | I35: ZSO_Visibility + Zmatana | J35: Email to Branch to confirm product details | K35: Email to Branch to confirm bundle details | L35: ZLOAD1 | P35: Email to Plant | Q35: Zload3 + ZSO_Auto | R35: VT01N
A36: Branch Email | B36: Before LS Creation | C36: SO Modification - Decrease | D36: =A36&" - "&B36&" - "&C36 -> Branch Email - Before LS Creation - SO Modification - Decrease | L36: ZLOAD1 | P36: Email to Plant | Q36: Zload3 + ZSO_Auto | R36: VT01N
A37: Branch Email | B37: Before LS Creation | C37: SO Modification - Delete | D37: =A37&" - "&B37&" - "&C37 -> Branch Email - Before LS Creation - SO Modification - Delete | L37: ZLOAD1 | P37: Email to Plant | Q37: Zload3 + ZSO_Auto | R37: VT01N
A38: Branch Email | B38: Before LS Creation | C38: SO Modification - Decrease + Delete | D38: =A38&" - "&B38&" - "&C38 -> Branch Email - Before LS Creation - SO Modification - Decrease + Delete | L38: ZLOAD1 | P38: Email to Plant | Q38: Zload3 + ZSO_Auto | R38: VT01N

Sheet Sheet2
A1: Case | B1: Status | C1: Requirement | E1: Build version
A2: 1. Multi-Plant Material Verification: Please set searching criteria to verify the same materials across different plants, as we produce the same items in multiple locations. | B2: Under Consideration | C2: Database needed | E2: P1 | F2: How to read | G2: Multi Plat code to be shared
A3: 2. Project and Special Discount Orders (ZLQF): The system needs to allow for the insertion of PAF and manual discounts in these orders. | B3: Explanation needed | C3: Need to check PAF is applied or not - seperate SAP transaction Channel 40, 45, 35 - except these channel PAF is applicable VA02 / VA03 check ZLQF - Liquidation Order - VA02 - itemwise checking is needed for order type ZLQF (P2) | D3: Seperate Session needed for PAF | E3: PAF - P1 ZLQF - P2 | F3: PAF | G3: email to be sent
A4: 3. Company Vehicles: Freight must be reflected in orders for all company vehicles. (To Be Billed orders) | B4: Explanation needed | C4: VA02 needs to be used (P2) | D4: Seperate Session needed | E4: P2
A5: 4. Antique Process: This remains pending as it involves a different workflow. | B5: Seperate Work Flow | E5: P2
A6: 5. Post-Clearance Changes: What process will apply if a dealer changes materials after dispatch clearance or truck placement? | B6: Listed in Sheet 1 | E6: P1
A7: 6. Physical Stock Discrepancies: How will existing orders be rectified if there is a physical stock issue at the plant after the truck has been placed for loading? | B7: Listed in Sheet 1 | E7: P1
A8: 7. Quantity and Batch Adjustments: During loading, plants often report shortages or batch changes (e.g., 98 boxes available instead of 100). We currently update the loading slip (LS) and bill accordingly. How will the program handle these real-time changes? | B8: Listed in Sheet 1 | C8: In cases where GRN to be made - P2 | E8: P2
A9: 8. Vehicle Number Changes: Vehicle numbers are frequently changed for local orders in Gujarat, Rajasthan, Maharashtra, and M.P. How will the system capture these updates? | B9: Explanation needed | C9: Modification on APplication to update Vehicle Detais | E9: P1 | G9: before invoce is generated
A10: 13. Container Diversion: How will the system manage cases where containers must be diverted to other orders due to quality issues, production problems, or sudden transporter changes by the dealers? | B10: Explanation needed | C10: Modification on APplication to update Vehicle Detais | E10: P1 | G10: before invoce is generated
A11: 9. Advance Billing (AB): What process will be implemented for advance billing orders? | B11: Seperate Work Flow | C11: P2 | E11: P2
A12: 10. New Order Creation: We often need to create new orders after receiving vendor invoices for various reasons. | B12: Listed in Sheet 1 | C12: While craeting HRJ Invoice - error comes up. _ Send email to Master Data Team & PMG. They will revert. 1. Upload again 2. Create a New Order & Process - VA02 - Second Release - ZSO_Auto This will be taken up along with Antique | D12: Seperate Session needed to reverse GRN | E12: P2
A13: 11. AB Logistics: For AB, we send the LS without transport details; the system must resend details once the vehicle is placed. The current process involves sending the LS to the plant for billing, receiving the invoice, and then providing loading details (LS number, boxes, and transportation) 1–2 days later. The plant then emails the e-way bill, packing list, and advance bill. | B13: Seperate Work Flow | C13: P2 | E13: P2
A14: 12. Partial Invoicing: If we send 5 LS for billing but only receive 4 invoices from the plant, we invoice those four and process the fifth the following day. How will the system handle this scenario? | B14: Explanation needed | C14: We have to define a process [28,29,30,31] Need seperate discussion | D14: Seperate Discussion needed to finalise process to be adopted | E14: P2

Sheet Sheet3
T1: Product Change From Branch Before LS | AE1: Product Change From Branch After LS Befor Vehicle Placement | AR1: Product Change From Branch After Vehicle Placement | BG1: Product Change From Branch After Email to Plant | BS1: Product Change From Plant Before Plant Invoice | CI1: Product Change From Branch After Plant Invoice
E2: Step 1 | F2: Step 2 | G2: Step 3 | H2: Step 4 | I2: Step 5 | J2: Step 6 | K2: Step 7 | L2: Step 8 | M2: Step 9 | N2: Step 10 | O2: Step 11 | P2: Step 12 | Q2: Step 13 | R2: Step 14 | S2: Step 15 | T2: Step 16 | U2: Step 17 | V2: Step 18 | W2: Step 19 | X2: Step 20 | Y2: Step 21 | Z2: Step 22 | AA2: Step 23 | AB2: Step 24 | AC2: Step 25 | AD2: Step 26 | AE2: Step 27 | AF2: Step 28 | AG2: Step 29 | AH2: Step 30 | AI2: Step 31 | AJ2: Step 32 | AK2: Step 33 | AL2: Step 34 | AM2: Step 35 | AN2: Step 36 | AO2: Step 37 | AP2: Step 38 | AQ2: Step 39 | AR2: Step 40 | AS2: Step 41 | AT2: Step 42 | AU2: Step 43 | AV2: Step 44 | AW2: Step 45 | AX2: Step 46 | AY2: Step 47 | AZ2: Step 48 | BA2: Step 49 | BB2: Step 50 | BC2: Step 51 | BD2: Step 52 | BE2: Step 53 | BF2: Step 54 | BG2: Step 55 | BH2: Step 56 | BI2: Step 57 | BJ2: Step 58 | BK2: Step 59 | BL2: Step 60 | BM2: Step 61 | BN2: Step 62 | BO2: Step 63 | BP2: Step 64 | BQ2: Step 65 | BR2: Step 66 | BS2: Step 67 | BT2: Step 68 | BU2: Step 69 | BV2: Step 70 | BW2: Step 71 | BX2: Step 72 | BY2: Step 73 | BZ2: Step 74 | CA2: Step 75 | CB2: Step 76 | CC2: Step 77 | CD2: Step 78 | CE2: Step 79 | CF2: Step 80 | CG2: Step 81 | CH2: Step 82 | CI2: Step 83 | CJ2: Step 84 | CK2: Step 85 | CL2: Step 86 | CM2: Step 87 | CN2: Step 88 | CO2: Step 89 | CP2: Step 90 | CQ2: Step 91 | CR2: Step 92 | CS2: Step 93 | CT2: Step 94 | CU2: Step 95 | CV2: Step 96
A3: Email Type | B3: Stage | C3: Primary Intent | D3: Augmented Intent | E3: Branch Email | F3: Discount Check | G3: Reply to Branch | H3: Reply From Branch | I3: ZSO Visibility + Zmatana | J3: Email to Branch to confirm product details | K3: Email From Branch confirming product details | L3: Email to Branch to confirm bundle details | M3: Email From Branch confirming bundle details | N3: MB51 Check | O3: ZSO Visibility + Zmatana | P3: Email to Branch to confirm product details | Q3: Email From Branch confirming product details | R3: Email to Branch to confirm bundle details | S3: Email From Branch confirming bundle details | T3: Email from branch changing Product | U3: Product Availability Check | V3: VA02 | W3: Email to Branch For Second Release | X3: Email from Branch confirming 2nd release | Y3: ZSO Visibility + Zmatana | Z3: Email to Branch to confirm product details | AA3: Email From Branch confirming product details | AB3: Email to Branch to confirm bundle details | AC3: Email From Branch confirming bundle details | AD3: ZLOAD1 | AE3: Email from branch changing Product | AF3: Product Availability Check | AG3: VA02 | AH3: Email to Branch For Second Release | AI3: Email from Branch confirming 2nd release | AJ3: ZSO Visibility + Zmatana | AK3: Email to Branch to confirm product details | AL3: Email From Branch confirming product details | AM3: Email to Branch to confirm bundle details | AN3: Email From Branch confirming bundle details | AO3: ZLOAD2 | AP3: ZLOAD Delete | AQ3: Email to Branch for Vehicle | AR3: Email from branch changing Product | AS3: Product Availability Check | AT3: VA02 | AU3: Email to Branch For Second Release | AV3: Email from Branch confirming 2nd release | AW3: ZSO Visibility + Zmatana | AX3: Email to Branch to confirm product details | AY3: Email From Branch confirming product details | AZ3: Email to Branch to confirm bundle details | BA3: Email From Branch confirming bundle details | BB3: ZLOAD2 | BC3: ZLOAD Delete | BD3: Email to Branch for Vehicle | BE3: Email From Branch | BF3: Email to Plant | BG3: Email from branch changing Product | BH3: Product Availability Check | BI3: VA02 | BJ3: Email to Branch For Second Release | BK3: Email from Branch confirming 2nd release | BL3: ZSO Visibility + Zmatana | BM3: Email to Branch to confirm product details | BN3: Email From Branch confirming product details | BO3: Email to Branch to confirm bundle details | BP3: Email From Branch confirming bundle details | BQ3: ZLOAD2 | BR3: ZLOAD Delete | BS3: Email from Plant changing Product | BT3: Email to Branch notifying plant change | BU3: Email from Branch acknowledging plant chage | BV3: Product Availability Check | BW3: VA02 | BX3: Email to Branch For Second Release | BY3: Email from Branch confirming 2nd release | BZ3: ZSO Visibility + Zmatana | CA3: Email to Branch to confirm product details | CB3: Email From Branch confirming product details | CC3: Email to Branch to confirm bundle details | CD3: Email From Branch confirming bundle details | CE3: ZLOAD2 | CF3: ZLOAD Delete | CG3: Email to Plant with LS | CH3: Email from Plant with Invoice | CI3: Email from branch changing Product | CJ3: Product Availability Check | CK3: VA02 | CL3: Email to Branch For Second Release | CM3: Email from Branch confirming 2nd release | CN3: ZSO Visibility + Zmatana | CO3: Email to Branch to confirm product details | CP3: Email From Branch confirming product details | CQ3: Email to Branch to confirm bundle details | CR3: Email From Branch confirming bundle details | CS3: ZLOAD2 | CT3: ZLOAD Delete | CU3: Zload3 + ZSO_Auto | CV3: VT01N
A4: ='Copy of Sheet1'!A3 -> Branch Email | B4: ='Copy of Sheet1'!B3 -> Before LS Creation | C4: ='Copy of Sheet1'!C3 -> New SO | D4: ='Copy of Sheet1'!D3 -> Branch Email - Before LS Creation - New SO | E4: 1 | F4: 1 | G4: 1 | H4: 1 | I4: 1 | J4: 1 | K4: 1 | L4: 1 | M4: 1 | AD4: 1 | AO4: 0 | AP4: 0 | AQ4: 1 | BE4: 1 | BF4: 1 | CH4: 1 | CU4: 1 | CV4: 1
A5: ='Copy of Sheet1'!A4 -> Branch Email | B5: ='Copy of Sheet1'!B4 -> Before LS Creation | C5: ='Copy of Sheet1'!C4 -> Second Release confirmation | D5: ='Copy of Sheet1'!D4 -> Branch Email - Before LS Creation - Second Release confirmation | X5: 1 | Y5: 1 | Z5: 1 | AA5: 1 | AB5: 1 | AC5: 1 | AD5: 1 | AQ5: 1 | BE5: 1 | BF5: 1 | CH5: 1 | CU5: 1 | CV5: 1
A6: ='Copy of Sheet1'!A5 -> Branch Email | B6: After LS Creation | C6: Second Release confirmation | D6: =A6&" - "&B6&" - "&C6 -> Branch Email - After LS Creation - Second Release confirmation | X6: 1 | Y6: 1 | Z6: 1 | AA6: 1 | AB6: 1 | AC6: 1 | AO6: 1 | AQ6: 1 | BE6: 1 | BF6: 1 | CH6: 1 | CU6: 1 | CV6: 1
A7: ='Copy of Sheet1'!A5 -> Branch Email | B7: ='Copy of Sheet1'!B5 -> Before LS Creation | C7: ='Copy of Sheet1'!C5 -> Discount Code Confirmation | D7: ='Copy of Sheet1'!D5 -> Branch Email - Before LS Creation - Discount Code Confirmation | H7: 1 | I7: 1 | J7: 1 | K7: 1 | L7: 1 | M7: 1 | AD7: 1 | AO7: 0 | AP7: 0 | AQ7: 1 | BE7: 1 | BF7: 1 | CH7: 1 | CU7: 1 | CV7: 1
A8: Branch Email | B8: ='Copy of Sheet1'!B6 -> Before LS Creation | C8: ='Copy of Sheet1'!C6 -> Vehicle Weight Clarification | D8: ='Copy of Sheet1'!D6 -> Branch Email - Before LS Creation - Vehicle Weight Clarification | M8: 1 | AD8: 1 | AO8: 0 | AP8: 0 | AQ8: 1 | BE8: 1 | BF8: 1 | CH8: 1 | CU8: 1 | CV8: 1
A9: Branch Email | B9: ='Copy of Sheet1'!B7 -> Anytime | C9: ='Copy of Sheet1'!C7 -> Seeking Order Update | D9: ='Copy of Sheet1'!D7 -> Branch Email - Anytime - Seeking Order Update
A10: Branch Email | B10: ='Copy of Sheet1'!B8 -> After LS Creation | C10: ='Copy of Sheet1'!C8 -> Sharing Vehicle Details | D10: ='Copy of Sheet1'!D8 -> Branch Email - After LS Creation - Sharing Vehicle Details | BE10: 1 | BF10: 1 | CH10: 1 | CU10: 1 | CV10: 1
A11: Branch Email | B11: ='Copy of Sheet1'!B9 -> Anytime | C11: ='Copy of Sheet1'!C9 -> Others | D11: ='Copy of Sheet1'!D9 -> Branch Email - Anytime - Others
A12: Branch Email | B12: ='Copy of Sheet1'!B10 -> Before LS Creation | C12: ='Copy of Sheet1'!C10 -> Product Clarification - Release All - No Change in SO quantity | D12: ='Copy of Sheet1'!D10 -> Branch Email - Before LS Creation - Product Clarification - Release All - No Change in SO quantity | K12: =K4 -> 1 | L12: =L4 -> 1 | M12: =M4 -> 1 | AD12: =AD4 -> 1 | AO12: =AO4 -> 0 | AP12: =AP4 -> 0 | AQ12: =AQ4 -> 1 | BE12: =BE4 -> 1 | BF12: =BF4 -> 1 | CH12: =CH4 -> 1 | CU12: =CU4 -> 1 | CV12: =CV4 -> 1
A13: Branch Email | B13: ='Copy of Sheet1'!B11 -> Before LS Creation | C13: ='Copy of Sheet1'!C11 -> Product Clarification - Release as available/part - Decrease in SO quantity | D13: ='Copy of Sheet1'!D11 -> Branch Email - Before LS Creation - Product Clarification - Release as available/part - Decrease in SO quantity | K13: =K4 -> 1 | L13: =L4 -> 1 | M13: =M4 -> 1 | AD13: =AD4 -> 1 | AO13: =AO4 -> 0 | AP13: =AP4 -> 0 | AQ13: =AQ4 -> 1 | BE13: =BE4 -> 1 | BF13: =BF4 -> 1 | CH13: =CH4 -> 1 | CU13: =CU4 -> 1 | CV13: =CV4 -> 1
A14: Branch Email | B14: ='Copy of Sheet1'!B12 -> Before LS Creation | C14: ='Copy of Sheet1'!C12 -> Product Clarification - Release with adjustment - Increase | D14: ='Copy of Sheet1'!D12 -> Branch Email - Before LS Creation - Product Clarification - Release with adjustment - Increase | K14: 1 | U14: 1 | V14: 1 | W14: 1 | X14: 1 | Y14: 1 | Z14: 1 | AA14: 1 | AB14: 1 | AC14: 1 | AD14: 1 | AQ14: 1 | BE14: 1 | BF14: 1 | CH14: 1 | CU14: 1 | CV14: 1
A15: Branch Email | B15: ='Copy of Sheet1'!B13 -> Before LS Creation | C15: ='Copy of Sheet1'!C13 -> Product Clarification - Release with adjustment - Increase + Decrease | D15: ='Copy of Sheet1'!D13 -> Branch Email - Before LS Creation - Product Clarification - Release with adjustment - Increase + Decrease | K15: 1 | U15: 1 | V15: 1 | W15: 1 | X15: 1 | Y15: 1 | Z15: 1 | AA15: 1 | AB15: 1 | AC15: 1 | AD15: 1 | AQ15: 1 | BE15: 1 | BF15: 1 | CH15: 1 | CU15: 1 | CV15: 1
A16: Branch Email | B16: ='Copy of Sheet1'!B14 -> Before LS Creation | C16: ='Copy of Sheet1'!C14 -> Product Clarification - Release with adjustment - Increase + Delete | D16: ='Copy of Sheet1'!D14 -> Branch Email - Before LS Creation - Product Clarification - Release with adjustment - Increase + Delete | K16: 1 | U16: 1 | V16: 1 | W16: 1 | X16: 1 | Y16: 1 | Z16: 1 | AA16: 1 | AB16: 1 | AC16: 1 | AD16: 1 | AQ16: 1 | BE16: 1 | BF16: 1 | CH16: 1 | CU16: 1 | CV16: 1
A17: Branch Email | B17: ='Copy of Sheet1'!B15 -> Before LS Creation | C17: ='Copy of Sheet1'!C15 -> Product Clarification - Release with adjustment - Delete | D17: ='Copy of Sheet1'!D15 -> Branch Email - Before LS Creation - Product Clarification - Release with adjustment - Delete | K17: 1 | Z17: 1 | AA17: 1 | AB17: 1 | AC17: 1 | AD17: 1 | AQ17: 1 | BE17: 1 | BF17: 1 | CH17: 1 | CU17: 1 | CV17: 1
A18: Branch Email | B18: ='Copy of Sheet1'!B16 -> Before LS Creation | C18: ='Copy of Sheet1'!C16 -> Product Clarification - Hold/Wait till all material available | D18: ='Copy of Sheet1'!D16 -> Branch Email - Before LS Creation - Product Clarification - Hold/Wait till all material available | N18: 1 | O18: 1 | P18: 1 | Q18: 1 | R18: 1 | S18: 1 | AD18: 1 | AQ18: 1 | BE18: 1 | BF18: 1 | CH18: 1 | CU18: 1 | CV18: 1
A19: Branch Email | B19: After LS Creation - Before Vehicle Placement | C19: ='Copy of Sheet1'!C17 -> SO Modification - Increase | D19: ='Copy of Sheet1'!D17 -> Branch Email - After LS Creation - SO Modification - Increase | AE19: 1 | AF19: 1 | AG19: 1 | AH19: 1 | AI19: 1 | AJ19: 1 | AK19: 1 | AL19: 1 | AM19: 1 | AN19: 1 | AO19: 1 | AQ19: 1 | BE19: 1 | BF19: 1 | CH19: 1 | CU19: 1 | CV19: 1
A20: Branch Email | B20: After LS Creation - Before Vehicle Placement | C20: ='Copy of Sheet1'!C18 -> SO Modification - Increase + Decrease | D20: ='Copy of Sheet1'!D18 -> Branch Email - After LS Creation - SO Modification - Increase + Decrease | AE20: 1 | AF20: 1 | AG20: 1 | AH20: 1 | AI20: 1 | AJ20: 1 | AK20: 1 | AL20: 1 | AM20: 1 | AN20: 1 | AO20: 1 | AQ20: 1 | BE20: 1 | BF20: 1 | CH20: 1 | CU20: 1 | CV20: 1
A21: Branch Email | B21: After LS Creation - Before Vehicle Placement | C21: ='Copy of Sheet1'!C19 -> SO Modification - Increase + Delete | D21: ='Copy of Sheet1'!D19 -> Branch Email - After LS Creation - SO Modification - Increase + Delete | AE21: 1 | AF21: 1 | AG21: 1 | AH21: 1 | AI21: 1 | AJ21: 1 | AK21: 1 | AL21: 1 | AM21: 1 | AN21: 1 | AO21: 1 | AP21: 1 | AQ21: 1 | BE21: 1 | BF21: 1 | CH21: 1 | CU21: 1 | CV21: 1
A22: Branch Email | B22: After LS Creation - Before Vehicle Placement | C22: ='Copy of Sheet1'!C20 -> SO Modification - Decrease | D22: ='Copy of Sheet1'!D20 -> Branch Email - After LS Creation - SO Modification - Decrease | AE22: 1 | AO22: 1 | AQ22: 1 | BE22: 1 | BF22: 1 | CH22: 1 | CU22: 1 | CV22: 1
A23: Branch Email | B23: After LS Creation - Before Vehicle Placement | C23: ='Copy of Sheet1'!C21 -> SO Modification - Delete | D23: ='Copy of Sheet1'!D21 -> Branch Email - After LS Creation - SO Modification - Delete | AE23: 1 | AP23: 1 | AQ23: 1 | BE23: 1 | BF23: 1 | CH23: 1 | CU23: 1 | CV23: 1
A24: Branch Email | B24: After LS Creation - Before Vehicle Placement | C24: ='Copy of Sheet1'!C22 -> SO Modification - Decrease + Delete | D24: ='Copy of Sheet1'!D22 -> Branch Email - AFter LS Creation - SO Modification - Decrease + Delete | AE24: 1 | AO24: 1 | AP24: 1 | AQ24: 1 | BE24: 1 | BF24: 1 | CH24: 1 | CU24: 1 | CV24: 1
A25: Branch Email | B25: After LS Creation - After Vehicle Placement | C25: SO Modification - Increase | D25: =A25&" - "&B25&" - "&C25 -> Branch Email - After LS Creation - After Vehicle Placement - SO Modification - Increase | AR25: 1 | AS25: 1 | AT25: 1 | AU25: 1 | AV25: 1 | AW25: 1 | AX25: 1 | AY25: 1 | AZ25: 1 | BA25: 1 | BB25: 1 | BD25: 1 | BE25: 1 | BF25: 1 | CH25: 1 | CU25: 1 | CV25: 1
A26: Branch Email | B26: After LS Creation - After Vehicle Placement | C26: SO Modification - Increase + Decrease | D26: =A26&" - "&B26&" - "&C26 -> Branch Email - After LS Creation - After Vehicle Placement - SO Modification - Increase + Decrease | AR26: 1 | AS26: 1 | AT26: 1 | AU26: 1 | AV26: 1 | AW26: 1 | AX26: 1 | AY26: 1 | AZ26: 1 | BA26: 1 | BB26: 1 | BD26: 1 | BE26: 1 | BF26: 1 | CH26: 1 | CU26: 1 | CV26: 1
A27: Branch Email | B27: After LS Creation - After Vehicle Placement | C27: SO Modification - Increase + Delete | D27: =A27&" - "&B27&" - "&C27 -> Branch Email - After LS Creation - After Vehicle Placement - SO Modification - Increase + Delete | AR27: 1 | AS27: 1 | AT27: 1 | AU27: 1 | AV27: 1 | AW27: 1 | AX27: 1 | AY27: 1 | AZ27: 1 | BA27: 1 | BB27: 1 | BC27: 1 | BD27: 1 | BE27: 1 | BF27: 1 | CH27: 1 | CU27: 1 | CV27: 1
A28: Branch Email | B28: After LS Creation - After Vehicle Placement | C28: SO Modification - Decrease | D28: =A28&" - "&B28&" - "&C28 -> Branch Email - After LS Creation - After Vehicle Placement - SO Modification - Decrease | AR28: 1 | BB28: 1 | BD28: 1 | BE28: 1 | BF28: 1 | CH28: 1 | CU28: 1 | CV28: 1
A29: Branch Email | B29: After LS Creation - After Vehicle Placement | C29: SO Modification - Delete | D29: =A29&" - "&B29&" - "&C29 -> Branch Email - After LS Creation - After Vehicle Placement - SO Modification - Delete | AR29: 1 | BC29: 1 | BD29: 1 | BE29: 1 | BF29: 1 | CH29: 1 | CU29: 1 | CV29: 1
A30: Branch Email | B30: After LS Creation - After Vehicle Placement | C30: SO Modification - Decrease + Delete | D30: =A30&" - "&B30&" - "&C30 -> Branch Email - After LS Creation - After Vehicle Placement - SO Modification - Decrease + Delete | AR30: 1 | BB30: 1 | BC30: 1 | BD30: 1 | BE30: 1 | BF30: 1 | CH30: 1 | CU30: 1 | CV30: 1
A31: Branch Email | B31: After LS Creation - After Email to Plant | C31: SO Modification - Increase | D31: =A31&" - "&B31&" - "&C31 -> Branch Email - After LS Creation - After Email to Plant - SO Modification - Increase | BG31: 1 | BH31: 1 | BI31: 1 | BJ31: 1 | BK31: 1 | BL31: 1 | BM31: 1 | BN31: 1 | BO31: 1 | BP31: 1 | BQ31: 1 | CH31: 1 | CU31: 1 | CV31: 1
A32: Branch Email | B32: After LS Creation - After Email to Plant | C32: SO Modification - Increase + Decrease | D32: =A32&" - "&B32&" - "&C32 -> Branch Email - After LS Creation - After Email to Plant - SO Modification - Increase + Decrease | BG32: 1 | BH32: 1 | BI32: 1 | BJ32: 1 | BK32: 1 | BL32: 1 | BM32: 1 | BN32: 1 | BO32: 1 | BP32: 1 | BQ32: 1 | CH32: 1 | CU32: 1 | CV32: 1
A33: Branch Email | B33: After LS Creation - After Email to Plant | C33: SO Modification - Increase + Delete | D33: =A33&" - "&B33&" - "&C33 -> Branch Email - After LS Creation - After Email to Plant - SO Modification - Increase + Delete | BG33: 1 | BH33: 1 | BI33: 1 | BJ33: 1 | BK33: 1 | BL33: 1 | BM33: 1 | BN33: 1 | BO33: 1 | BP33: 1 | BQ33: 1 | BR33: 1 | CH33: 1 | CU33: 1 | CV33: 1
A34: Branch Email | B34: After LS Creation - After Email to Plant | C34: SO Modification - Decrease | D34: =A34&" - "&B34&" - "&C34 -> Branch Email - After LS Creation - After Email to Plant - SO Modification - Decrease | BG34: 1 | BQ34: 1 | CH34: 1 | CU34: 1 | CV34: 1
A35: Branch Email | B35: After LS Creation - After Email to Plant | C35: SO Modification - Delete | D35: =A35&" - "&B35&" - "&C35 -> Branch Email - After LS Creation - After Email to Plant - SO Modification - Delete | BG35: 1 | BR35: 1 | CH35: 1 | CU35: 1 | CV35: 1
A36: Branch Email | B36: After LS Creation - After Email to Plant | C36: SO Modification - Decrease + Delete | D36: =A36&" - "&B36&" - "&C36 -> Branch Email - After LS Creation - After Email to Plant - SO Modification - Decrease + Delete | BG36: 1 | BQ36: 1 | BR36: 1 | CH36: 1 | CU36: 1 | CV36: 1
A37: Branch Email | B37: After LS Creation - After Plant Invoice | C37: SO Modification - Increase | D37: =A37&" - "&B37&" - "&C37 -> Branch Email - After LS Creation - After Plant Invoice - SO Modification - Increase | CI37: 1 | CJ37: 1 | CK37: 1 | CL37: 1 | CM37: 1 | CN37: 1 | CO37: 1 | CP37: 1 | CQ37: 1 | CR37: 1 | CS37: 1 | CU37: 1 | CV37: 1
A38: Branch Email | B38: After LS Creation - After Plant Invoice | C38: SO Modification - Increase + Decrease | D38: =A38&" - "&B38&" - "&C38 -> Branch Email - After LS Creation - After Plant Invoice - SO Modification - Increase + Decrease | CI38: 1 | CJ38: 1 | CK38: 1 | CL38: 1 | CM38: 1 | CN38: 1 | CO38: 1 | CP38: 1 | CQ38: 1 | CR38: 1 | CS38: 1 | CU38: 1 | CV38: 1
A39: Branch Email | B39: After LS Creation - After Plant Invoice | C39: SO Modification - Increase + Delete | D39: =A39&" - "&B39&" - "&C39 -> Branch Email - After LS Creation - After Plant Invoice - SO Modification - Increase + Delete | CI39: 1 | CJ39: 1 | CK39: 1 | CL39: 1 | CM39: 1 | CN39: 1 | CO39: 1 | CP39: 1 | CQ39: 1 | CR39: 1 | CS39: 1 | CT39: 1 | CU39: 1 | CV39: 1
A40: Branch Email | B40: After LS Creation - After Plant Invoice | C40: SO Modification - Decrease | D40: =A40&" - "&B40&" - "&C40 -> Branch Email - After LS Creation - After Plant Invoice - SO Modification - Decrease | CI40: 1 | CS40: 1 | CU40: 1 | CV40: 1
...
